Workbook

Sheet 📋 CONSULTA
I1: row idx → | J1: =IF(AND(E2="",E3=""),0,IFERROR(IF(E3<>"",MATCH(E3,'CADASTRO LOJAS'!B3:B230,0),IFERROR(MATCH(VALUE(E2),'CADASTRO LOJAS'!A3:A230,0),IFERROR(MATCH("*"&SUBSTITUTE(SUBSTITUTE(SUBSTITUTE(SUBSTITUTE(E2,".",""),"/",""),"-","")," ","")&"*",'CADASTRO LOJAS'!AK3:AK230,0),IFERROR(MATCH("*"&E2&"*",'CADASTRO LOJAS'!B3:B230,0),IFERROR(MATCH("*"&E2&"*",'CADASTRO LOJAS'!C3:C230,0),MATCH("*"&E2&"*",'CADASTRO LOJAS'!L3:L230,0)))))),0)) -> 9
B2: 🔍 BUSCAR LOJA (código, CNPJ, nome, razão social ou cidade):
B3: Ou selecione da lista: | E3: 009 - Js
B5: 🔵 IDENTIFICAÇÃO | F5: 🟢 LOCALIZAÇÃO
B6: Código: | C6: {=IFERROR(IF($J$1=0,"—",IF(INDEX('CADASTRO LOJAS'!A:A,$J$1+2)="","—",INDEX('CADASTRO LOJAS'!A:A,$J$1+2))),"—")} -> 9 | F6: Logradouro: | G6: {=IFERROR(IF($J$1=0,"—",IF(INDEX('CADASTRO LOJAS'!H:H,$J$1+2)="","—",INDEX('CADASTRO LOJAS'!H:H,$J$1+2))),"—")} -> Avenida Andrômeda
B7: Nome Fantasia: | C7: {=IFERROR(IF($J$1=0,"—",IF(INDEX('CADASTRO LOJAS'!B:B,$J$1+2)="","—",INDEX('CADASTRO LOJAS'!B:B,$J$1+2))),"—")} -> 009 - Js | F7: Número: | G7: {=IFERROR(IF($J$1=0,"—",IF(INDEX('CADASTRO LOJAS'!I:I,$J$1+2)="","—",INDEX('CADASTRO LOJAS'!I:I,$J$1+2))),"—")} -> 1868
B8: Razão Social: | C8: {=IFERROR(IF($J$1=0,"—",IF(INDEX('CADASTRO LOJAS'!C:C,$J$1+2)="","—",INDEX('CADASTRO LOJAS'!C:C,$J$1+2))),"—")} -> Oscar Calcados Ltda | F8: Bairro: | G8: {=IFERROR(IF($J$1=0,"—",IF(INDEX('CADASTRO LOJAS'!K:K,$J$1+2)="","—",INDEX('CADASTRO LOJAS'!K:K,$J$1+2))),"—")} -> Jardim Satélite
B9: CNPJ: | C9: {=IFERROR(IF($J$1=0,"—",IF(INDEX('CADASTRO LOJAS'!D:D,$J$1+2)="","—",INDEX('CADASTRO LOJAS'!D:D,$J$1+2))),"—")} -> 50.915.875/0001-91 | F9: Cidade: | G9: {=IFERROR(IF($J$1=0,"—",IF(INDEX('CADASTRO LOJAS'!L:L,$J$1+2)="","—",INDEX('CADASTRO LOJAS'!L:L,$J$1+2))),"—")} -> São José Dos Campos
B10: Status: | C10: {=IFERROR(IF($J$1=0,"—",IF(INDEX('CADASTRO LOJAS'!E:E,$J$1+2)="","—",INDEX('CADASTRO LOJAS'!E:E,$J$1+2))),"—")} -> Aberta | F10: UF: | G10: {=IFERROR(IF($J$1=0,"—",IF(INDEX('CADASTRO LOJAS'!M:M,$J$1+2)="","—",INDEX('CADASTRO LOJAS'!M:M,$J$1+2))),"—")} -> SP
B11: Unidade Negócio: | C11: {=IFERROR(IF($J$1=0,"—",IF(INDEX('CADASTRO LOJAS'!F:F,$J$1+2)="","—",INDEX('CADASTRO LOJAS'!F:F,$J$1+2))),"—")} -> Grupo Oscar Calçados | F11: CEP: | G11: {=IFERROR(IF($J$1=0,"—",IF(INDEX('CADASTRO LOJAS'!N:N,$J$1+2)="","—",INDEX('CADASTRO LOJAS'!N:N,$J$1+2))),"—")} -> 12230-001
B12: Grupo Financeiro: | C12: {=IFERROR(IF($J$1=0,"—",IF(INDEX('CADASTRO LOJAS'!G:G,$J$1+2)="","—",INDEX('CADASTRO LOJAS'!G:G,$J$1+2))),"—")} -> Grupo F1 | F12: Regional: | G12: {=IFERROR(IF($J$1=0,"—",IF(INDEX('CADASTRO LOJAS'!O:O,$J$1+2)="","—",INDEX('CADASTRO LOJAS'!O:O,$J$1+2))),"—")} -> PETERSON
B14: 🟡 CONTATOS | F14: 🟣 OPERAÇÃO
B15: Telefone: | C15: {=IFERROR(IF($J$1=0,"—",IF(INDEX('CADASTRO LOJAS'!Q:Q,$J$1+2)="","—",INDEX('CADASTRO LOJAS'!Q:Q,$J$1+2))),"—")} -> (12) 3932-0066 | F15: Hora Abertura: | G15: {=IFERROR(IF($J$1=0,"—",IF(INDEX('CADASTRO LOJAS'!U:U,$J$1+2)="","—",INDEX('CADASTRO LOJAS'!U:U,$J$1+2))),"—")} -> 0.375
B16: WhatsApp: | C16: {=IFERROR(IF($J$1=0,"—",IF(INDEX('CADASTRO LOJAS'!R:R,$J$1+2)="","—",INDEX('CADASTRO LOJAS'!R:R,$J$1+2))),"—")} -> (12) 97404-1272 | F16: Hora Fechamento: | G16: {=IFERROR(IF($J$1=0,"—",IF(INDEX('CADASTRO LOJAS'!V:V,$J$1+2)="","—",INDEX('CADASTRO LOJAS'!V:V,$J$1+2))),"—")} -> 0.79166667
B17: E-mail Loja: | C17: {=IFERROR(IF($J$1=0,"—",IF(INDEX('CADASTRO LOJAS'!S:S,$J$1+2)="","—",INDEX('CADASTRO LOJAS'!S:S,$J$1+2))),"—")} -> loja009@oscarcalcados.com.br
B18: E-mail Gerente: | C18: {=IFERROR(IF($J$1=0,"—",IF(INDEX('CADASTRO LOJAS'!T:T,$J$1+2)="","—",INDEX('CADASTRO LOJAS'!T:T,$J$1+2))),"—")} -> gerente009@oscarcalcados.com.br
B19: Diretor: | C19: {=IFERROR(IF($J$1=0,"—",IF(INDEX('CADASTRO LOJAS'!P:P,$J$1+2)="","—",INDEX('CADASTRO LOJAS'!P:P,$J$1+2))),"—")} -> ERICSON
B21: 🟠 INFRAESTRUTURA TI | F21: 🔴 SISTEMAS
B22: IP: | C22: {=IFERROR(IF($J$1=0,"—",IF(INDEX('CADASTRO LOJAS'!W:W,$J$1+2)="","—",INDEX('CADASTRO LOJAS'!W:W,$J$1+2))),"—")} -> — | F22: Versão MegaStore: | G22: {=IFERROR(IF($J$1=0,"—",IF(INDEX('CADASTRO LOJAS'!AD:AD,$J$1+2)="","—",INDEX('CADASTRO LOJAS'!AD:AD,$J$1+2))),"—")} -> —
B23: Link Internet: | C23: {=IFERROR(IF($J$1=0,"—",IF(INDEX('CADASTRO LOJAS'!X:X,$J$1+2)="","—",INDEX('CADASTRO LOJAS'!X:X,$J$1+2))),"—")} -> — | F23: Versão Retaguarda: | G23: {=IFERROR(IF($J$1=0,"—",IF(INDEX('CADASTRO LOJAS'!AE:AE,$J$1+2)="","—",INDEX('CADASTRO LOJAS'!AE:AE,$J$1+2))),"—")} -> —
B24: Operadora: | C24: {=IFERROR(IF($J$1=0,"—",IF(INDEX('CADASTRO LOJAS'!Y:Y,$J$1+2)="","—",INDEX('CADASTRO LOJAS'!Y:Y,$J$1+2))),"—")} -> — | F24: Versão Frente: | G24: {=IFERROR(IF($J$1=0,"—",IF(INDEX('CADASTRO LOJAS'!AF:AF,$J$1+2)="","—",INDEX('CADASTRO LOJAS'!AF:AF,$J$1+2))),"—")} -> —
B25: Tipo Conexão: | C25: {=IFERROR(IF($J$1=0,"—",IF(INDEX('CADASTRO LOJAS'!Z:Z,$J$1+2)="","—",INDEX('CADASTRO LOJAS'!Z:Z,$J$1+2))),"—")} -> — | F25: Ambiente: | G25: {=IFERROR(IF($J$1=0,"—",IF(INDEX('CADASTRO LOJAS'!AG:AG,$J$1+2)="","—",INDEX('CADASTRO LOJAS'!AG:AG,$J$1+2))),"—")} -> Beta
B26: PDVs: | C26: {=IFERROR(IF($J$1=0,"—",IF(INDEX('CADASTRO LOJAS'!AA:AA,$J$1+2)="","—",INDEX('CADASTRO LOJAS'!AA:AA,$J$1+2))),"—")} -> — | F26: Homologação: | G26: {=IFERROR(IF($J$1=0,"—",IF(INDEX('CADASTRO LOJAS'!AH:AH,$J$1+2)="","—",INDEX('CADASTRO LOJAS'!AH:AH,$J$1+2))),"—")} -> —
B27: Servidor Local: | C27: {=IFERROR(IF($J$1=0,"—",IF(INDEX('CADASTRO LOJAS'!AB:AB,$J$1+2)="","—",INDEX('CADASTRO LOJAS'!AB:AB,$J$1+2))),"—")} -> — | F27: Última Atualização: | G27: {=IFERROR(IF($J$1=0,"—",IF(INDEX('CADASTRO LOJAS'!AJ:AJ,$J$1+2)="","—",INDEX('CADASTRO LOJAS'!AJ:AJ,$J$1+2))),"—")} -> Última validação:
B28: Modelo Equip.: | C28: {=IFERROR(IF($J$1=0,"—",IF(INDEX('CADASTRO LOJAS'!AC:AC,$J$1+2)="","—",INDEX('CADASTRO LOJAS'!AC:AC,$J$1+2))),"—")} -> —
B30: ⚪ OBSERVAÇÕES
B31: Notas: | C31: {=IFERROR(IF($J$1=0,"—",IF(INDEX('CADASTRO LOJAS'!AI:AI,$J$1+2)="","—",INDEX('CADASTRO LOJAS'!AI:AI,$J$1+2))),"—")} -> —
B33: =IF($J$1=0,IF(AND(E2="",E3=""),"↑ Digite o código ou selecione uma loja acima.","⚠️ Loja não encontrada. Verifique o código ou nome."),"✅ Loja encontrada — dados exibidos acima.") -> ✅ Loja encontrada — dados exibidos acima.

Sheet CADASTRO LOJAS
A1: 🔵 IDENTIFICAÇÃO | H1: 🟢 LOCALIZAÇÃO | Q1: 🟡 CONTATOS | U1: 🟣 OPERAÇÃO | W1: 🟠 INFRAESTRUTURA TI | AD1: 🔴 SISTEMAS | AI1: ⚪ OBSERVAÇÕES
A2: Código Loja | B2: Nome Fantasia | C2: Razão Social | D2: CNPJ | E2: Status | F2: Unidade de Negócio | G2: Grupo Financeiro | H2: Logradouro | I2: Número | J2: Complemento (Endereço Lojas) | K2: Bairro | L2: Cidade | M2: UF | N2: CEP | O2: Regional | P2: Diretor | Q2: Telefone Loja | R2: WhatsApp | S2: E-mail Loja | T2: E-mail Gerente | U2: Hora Abertura | V2: Hora Fechamento | W2: IP | X2: Link de Internet | Y2: Operadora | Z2: Tipo de Conexão | AA2: Qtde PDVs | AB2: Servidor Local (S/N) | AC2: Modelo de Equipamento | AD2: Versão MegaStore | AE2: Versão Retaguarda | AF2: Versão Frente | AG2: Ambiente (Produção/Beta) | AH2: Homologação | AI2: Observações | AJ2: Última Atualização | AK2: CNPJ_digitos
A3: 1 | B3: 001 - Cl2 | C3: Oscar Calcados Ltda | D3: 50.915.875/0012-44 | E3: Aberta | F3: Grupo Oscar Calçados | G3: Grupo F1 | H3: Rua Sete De Setembro | I3: 344 | J3: Rua Sete de Setembro | K3: Centro | L3: São José Dos Campos | M3: SP | N3: 12210-260 | O3: LUIS AMERICO | P3: ERICSON | Q3: (12) 3908-9009 | R3: 12 997409-3794 | S3: loja001@oscarcalcados.com.br | T3: gerente001@oscarcalcados.com.br | U3: 0.375 | V3: 0.79166667 | AG3: Produção | AJ3: Última validação: | AK3: =IFERROR(__xludf.DUMMYFUNCTION("ARRAYFORMULA(IF(D3:D230="""","""",REGEXREPLACE(D3:D230&"""",""[^0-9]"","""")))"),"50915875001244") -> 50915875001244
A4: 2 | B4: 002 - Jp | C4: E N Constantino Calcados Eireli | D4: 54.237.938/0001-59 | E4: Aberta | F4: Grupo Oscar Calçados | G4: Grupo F7 | H4: Avenida Pedro Álvares Cabral | I4: 905 | J4: Avenida Pedro Álvares Cabral | K4: Jardim Paulista | L4: São José Dos Campos | M4: SP | N4: 12216-000 | O4: LUIS AMERICO | P4: ERICSON | Q4: (12) 3928-7884 | R4: (12) 97402-0423 | S4: loja002@oscarcalcados.com.br | T4: gerente002@oscarcalcados.com.br | U4: 0.375 | V4: 0.79166667 | AG4: Beta | AJ4: Última validação: | AK4: =IFERROR(__xludf.DUMMYFUNCTION("""COMPUTED_VALUE"""),"54237938000159") -> 54237938000159
A5: 3 | B5: 003 - Cl 1 | C5: Oscar Calcados Ltda | D5: 50.915.875/0013-25 | E5: Aberta | F5: Grupo Oscar Calçados | G5: Grupo F1 | H5: Rua Sete De Setembro | I5: 142 | J5: Rua Sete de Setembro | K5: Centro | L5: São José Dos Campos | M5: SP | N5: 12210-260 | O5: LUIS AMERICO | P5: ERICSON | Q5: (12) 3909-1311 | R5: (12) 97410-6235 | S5: loja003@oscarcalcados.com.br | T5: gerente003@oscarcalcados.com.br | U5: 0.375 | V5: 0.79166667 | AG5: Produção | AJ5: Última validação: | AK5: =IFERROR(__xludf.DUMMYFUNCTION("""COMPUTED_VALUE"""),"50915875001325") -> 50915875001325
A6: 4 | B6: 004 - Jc 2 | C6: Oscar Calcados Ltda | D6: 50.915.875/0014-06 | E6: Aberta | F6: Grupo Oscar Calçados | G6: Grupo F1 | H6: Rua Sargento Acrísio Santana | I6: 141 | J6: Rua Sargento Acrísio Santana, 149 | K6: Centro | L6: Jacareí | M6: SP | N6: 12327-320 | O6: MAURICIO | P6: ERICSON | Q6: (12) 3951-8988 | R6: (12) 97406-6835 | S6: loja004@oscarcalcados.com.br | T6: gerente004@oscarcalcados.com.br | U6: 0.375 | V6: 0.79166667 | AG6: Produção | AJ6: Última validação: | AK6: =IFERROR(__xludf.DUMMYFUNCTION("""COMPUTED_VALUE"""),"50915875001406") -> 50915875001406
A7: 5 | B7: 005 - Jc 1 | C7: Racso Calcados Ltda | D7: 72.014.681/0001-58 | E7: Aberta | F7: Grupo Oscar Calçados | G7: Grupo F7 | H7: Praça Raul Chaves | I7: 79 | J7: Praça Raul Chaves | K7: Centro | L7: Jacareí | M7: SP | N7: 12308-011 | O7: MAURICIO | P7: ERICSON | Q7: (12) 3954-0797 | R7: (12) 97406-7534 | S7: loja005@oscarcalcados.com.br | T7: gerente005@oscarcalcados.com.br | U7: 0.375 | V7: 0.79166667 | AG7: Produção | AJ7: Última validação: | AK7: =IFERROR(__xludf.DUMMYFUNCTION("""COMPUTED_VALUE"""),"72014681000158") -> 72014681000158
A8: 6 | B8: 006 - Sh 2 | C8: Oscar Calcados Ltda | D8: 50.915.875/0004-34 | E8: Aberta | F8: Grupo Oscar Calçados | G8: Grupo F1 | H8: Avenida Deputado Benedito Matarazzo | I8: 9403 | J8: Avenida Deputado Benedito Matarazzo | K8: Jardim Oswaldo Cruz | L8: São José Dos Campos | M8: SP | N8: 12215-900 | O8: LUIS AMERICO | P8: ERICSON | Q8: (12) 3924-3420 | R8: (12) 97408-3216 | S8: loja006@oscarcalcados.com.br | T8: gerente006@oscarcalcados.com.br | U8: 0.41666667 | V8: 0.91666667 | AG8: Produção | AJ8: Última validação: | AK8: =IFERROR(__xludf.DUMMYFUNCTION("""COMPUTED_VALUE"""),"50915875000434") -> 50915875000434
A9: 7 | B9: 007 - Cn | C9: Oscar Calcados Ltda | D9: 50.915.875/0003-53 | E9: Aberta | F9: Grupo Oscar Calçados | G9: Grupo F1 | H9: Avenida São João | I9: 2200 | J9: Avenida São João | K9: Jardim Das Colinas | L9: São José Dos Campos | M9: SP | N9: 12242-000 | O9: PETERSON | P9: ERICSON | Q9: (12) 3924-3432 | R9: (12) 97411-7843 | S9: loja007@oscarcalcados.com.br | T9: gerente007@oscarcalcados.com.br | U9: 0.41666667 | V9: 0.91666667 | AG9: Produção | AJ9: Última validação: | AK9: =IFERROR(__xludf.DUMMYFUNCTION("""COMPUTED_VALUE"""),"50915875000353") -> 50915875000353
A10: 8 | B10: 008 - Rio Preto Shopp | C10: Oscar Calcados Ltda | D10: 50.915.875/0044-21 | E10: Aberta | F10: Grupo Oscar Calçados | G10: Grupo F1 | H10: Avenida Brigadeiro Faria Lima | I10: 6363 | J10: Avenida Brigadeiro Faria Lima | K10: Vila Sao Jose | L10: Sao Jose Do Rio Preto | M10: SP | N10: 15090-000 | O10: ROGERS | P10: ERICSON | Q10: (17) 3201-2923 | R10: (17) 97400-8780 | S10: loja008@oscarcalcados.com.br | T10: gerente008@oscarcalcados.com.br | U10: 0.41666667 | V10: 0.91666667 | AG10: Produção | AJ10: Última validação: | AK10: =IFERROR(__xludf.DUMMYFUNCTION("""COMPUTED_VALUE"""),"50915875004421") -> 50915875004421
A11: 9 | B11: 009 - Js | C11: Oscar Calcados Ltda | D11: 50.915.875/0001-91 | E11: Aberta | F11: Grupo Oscar Calçados | G11: Grupo F1 | H11: Avenida Andrômeda | I11: 1868 | J11: Av. Andrômeda, 1868 | K11: Jardim Satélite | L11: São José Dos Campos | M11: SP | N11: 12230-001 | O11: PETERSON | P11: ERICSON | Q11: (12) 3932-0066 | R11: (12) 97404-1272 | S11: loja009@oscarcalcados.com.br | T11: gerente009@oscarcalcados.com.br | U11: 0.375 | V11: 0.79166667 | AG11: Beta | AJ11: Última validação: | AK11: =IFERROR(__xludf.DUMMYFUNCTION("""COMPUTED_VALUE"""),"50915875000191") -> 50915875000191
A12: 10 | B12: 010 - Cd Oscar | C12: Oscar Calcados Ltda | D12: 50.915.875/0005-15 | E12: Aberta | F12: Grupo Oscar Calçados | G12: Grupo F1 | H12: Rua Paraibuna | I12: 1692 | K12: Vila Nair | L12: São José Dos Campos | M12: SP | N12: 12231-010 | O12: LOJA FECHADA | P12: RENAN | AG12: Produção | AK12: =IFERROR(__xludf.DUMMYFUNCTION("""COMPUTED_VALUE"""),"50915875000515") -> 50915875000515
A13: 11 | B13: 011 - Arezzo Vale Sul Shopp | C13: Avs Comercio De Calcados Ltda | D13: 09.108.526/0001-64 | E13: Aberta | F13: Grupo Arezzo | G13: Grupo F9 | H13: Avenida Andromeda | I13: 227 | J13: Av. Andrômeda, 227 - Loja 204 | K13: Jardim Satelite | L13: Sao Jose Dos Campos | M13: SP | N13: 12230-001 | O13: VIVIANE | P13: SONIA | Q13: (12) 3935-4056 | R13: (12) 97411-6754 | S13: loja011@lojasarezzo.com.br | T13: gerente011@lojasarezzo.com.br | U13: 0.41666667 | V13: 0.91666667 | AG13: Produção | AJ13: Última validação: | AK13: =IFERROR(__xludf.DUMMYFUNCTION("""COMPUTED_VALUE"""),"09108526000164") -> 09108526000164
A14: 12 | B14: 012 - Arezzo Center Vale | C14: R Constantino Calcados Ltda | D14: 02.139.784/0001-69 | E14: Aberta | F14: Grupo Arezzo | G14: Grupo F9 | H14: Avenida Deputado Benedito Matarazzo | I14: 9403 | J14: Av. Dep. Benedito Matarazzo, 9403 Loja S/113 | K14: Jardim Oswaldo Cruz | L14: Sao Jose Dos Campos | M14: SP | N14: 12216-580 | O14: VIVIANE | P14: SONIA | Q14: (12) 3947-7619 | R14: (12) 97404-4892 | S14: loja012@lojasarezzo.com.br | T14: gerente012@lojasarezzo.com.br | U14: 0.41666667 | V14: 0.91666667 | AG14: Produção | AJ14: Última validação: | AK14: =IFERROR(__xludf.DUMMYFUNCTION("""COMPUTED_VALUE"""),"02139784000169") -> 02139784000169
A15: 13 | B15: 013 - Arezzo Shopp Colinas | C15: Ofs Comercio De Calcados Ltda | D15: 08.371.232/0001-68 | E15: Aberta | F15: Grupo Arezzo | G15: Grupo F9 | H15: Avenida São João | I15: 2200 | J15: São João, 2200 lj. Nº 010/011 | K15: Jardim Das Colinas | L15: São José Dos Campos | M15: SP | N15: 12242-000 | O15: VIVIANE | P15: SONIA | Q15: (12) 3904-7850 | R15: (12) 97411-5572 | S15: loja013@lojasarezzo.com.br | T15: gerente013@lojasarezzo.com.br | U15: 0.41666667 | V15: 0.91666667 | AG15: Produção | AJ15: Última validação: | AK15: =IFERROR(__xludf.DUMMYFUNCTION("""COMPUTED_VALUE"""),"08371232000168") -> 08371232000168
A16: 15 | B16: 015 - Victor Hugo Cv | C16: Iacr Comercial Ltda | D16: 04.723.248/0001-31 | E16: Aberta | F16: Grupo Victor Hugo | G16: Grupo F9 | H16: Avenida Deputado Benedito Matarazzo | I16: 9403 | J16: Av. Dep. Benedito Matarazzo, lj 509/10 | K16: Jardim Oswaldo Cruz | L16: São José Dos Campos | M16: SP | N16: 12216-580 | O16: SUILA | P16: SONIA | Q16: (12) 3928-7895 | R16: (12) 97407-7463 | S16: centervale@victorhugo.com.br | U16: 0.41666667 | V16: 0.91666667 | AG16: Produção | AJ16: Última validação: | AK16: =IFERROR(__xludf.DUMMYFUNCTION("""COMPUTED_VALUE"""),"04723248000131") -> 04723248000131
A17: 16 | B17: 016 - Guara Ct | C17: Oscar Calcados Ltda | D17: 50.915.875/0015-97 | E17: Aberta | F17: Grupo Oscar Calçados | G17: Grupo F1 | H17: Rua Comendador João Galvão | I17: 36 | J17: Rua Comendador João Galvão | K17: Centro | L17: Guaratinguetá | M17: SP | N17: 12500-150 | O17: THIAGO | P17: ERICSON | Q17: (12) 3128-3197 | R17: (12) 97411-1083 | S17: loja016@oscarcalcados.com.br | T17: gerente016@oscarcalcados.com.br | U17: 0.375 | V17: 0.79166667 | AG17: Produção | AJ17: Última validação: | AK17: =IFERROR(__xludf.DUMMYFUNCTION("""COMPUTED_VALUE"""),"50915875001597") -> 50915875001597
A18: 17 | B18: 017 - Tênis Vs | C18: Vsc Calcados Ltda | D18: 05.574.086/0001-80 | E18: Aberta | F18: Grupo Oscar Calçados | G18: Grupo F7 | H18: Avenida Andrômeda | I18: 227 | J18: Avenida Andrômeda | K18: Jardim Satélite | L18: São José Dos Campos | M18: SP | N18: 12230-000 | O18: PETERSON | P18: ERICSON | Q18: (12) 3935-4063 | R18: (12) 97402-7510 | S18: loja017@oscarcalcados.com.br | T18: gerente017@oscarcalcados.com.br | U18: 0.41666667 | V18: 0.91666667 | AG18: Produção | AJ18: Última validação: | AK18: =IFERROR(__xludf.DUMMYFUNCTION("""COMPUTED_VALUE"""),"05574086000180") -> 05574086000180
A19: 18 | B19: 018 - Arezzo Jacarei Shopp | C19: Arsj Comercio De Calcados Ltda | D19: 14.620.014/0001-12 | E19: Aberta | F19: Grupo Arezzo | G19: Grupo F9 | H19: Rua Barão De Jacareí | I19: 364 | J19: Rua Barão de Jacareí, 364 lj. 23 | K19: Centro | L19: Jacareí | M19: SP | N19: 12308-001 | O19: VIVIANE | P19: SONIA | Q19: (12) 3954-8385 | R19: (12) 97411-3673 | S19: loja018@lojasarezzo.com.br | T19: gerente018@lojasarezzo.com.br | U19: 0.41666667 | V19: 0.91666667 | AG19: Produção | AJ19: Última validação: | AK19: =IFERROR(__xludf.DUMMYFUNCTION("""COMPUTED_VALUE"""),"14620014000112") -> 14620014000112
A20: 19 | B20: 019 - Jc Sh | C20: Oscar Calcados Ltda | D20: 50.915.875/0016-78 | E20: Aberta | F20: Grupo Oscar Calçados | G20: Grupo F1 | H20: Rua Barão De Jacareí | I20: 364 | J20: Rua Barão de Jacareí | K20: Centro | L20: Jacareí | M20: SP | N20: 12308-001 | O20: MAURICIO | P20: ERICSON | Q20: (12) 3955-9599 | R20: (12) 97411-7172 | S20: loja019@oscarcalcados.com.br | T20: gerente019@oscarcalcados.com.br | U20: 0.41666667 | V20: 0.91666667 | AG20: Produção | AJ20: Última validação: | AK20: =IFERROR(__xludf.DUMMYFUNCTION("""COMPUTED_VALUE"""),"50915875001678") -> 50915875001678
A21: 20 | B21: 020 - Taub Shopp | C21: Oscar Calcados Ltda | D21: 50.915.875/0017-59 | E21: Aberta | F21: Grupo Oscar Calçados | G21: Grupo F1 | H21: Avenida Charles Schnneider | I21: 1700 | J21: Avenida Charles Schnneider | K21: Parque Senhor Do Bonfim | L21: Taubaté | M21: SP | N21: 12040-900 | O21: ESTEFAN | P21: ERICSON | Q21: (12) 3634-3637 | R21: (12) 97411-5917 | S21: loja020@oscarcalcados.com.br | T21: gerente020@oscarcalcados.com.br | U21: 0.41666667 | V21: 0.91666667 | AG21: Produção | AJ21: Última validação: | AK21: =IFERROR(__xludf.DUMMYFUNCTION("""COMPUTED_VALUE"""),"50915875001759") -> 50915875001759
A22: 22 | B22: 022 - Tenis Calçadão | C22: Jsc Comercio De Calcados Ltda | D22: 05.908.530/0001-56 | E22: Fechada | F22: Grupo Oscar Calçados | G22: Grupo F7 | H22: Rua Sete De Setembro | I22: 156 | J22: Rua Sete de Setembro | K22: Centro | L22: São José Dos Campos | M22: SP | N22: 12210-260 | O22: LUIS AMERICO | P22: ERICSON | Q22: (12) 3908-9006 | R22: (12) 97411-1976 | S22: loja022@oscarcalcados.com.br | T22: gerente022@oscarcalcados.com.br | U22: 0.375 | V22: 0.79166667 | AG22: Produção | AJ22: Última validação: | AK22: =IFERROR(__xludf.DUMMYFUNCTION("""COMPUTED_VALUE"""),"05908530000156") -> 05908530000156
A23: 23 | B23: 023 - Guará Shopp | C23: Oscar Calcados Ltda | D23: 50.915.875/0018-30 | E23: Aberta | F23: Grupo Oscar Calçados | G23: Grupo F1 | H23: Avenida Juscelino Kubitschek De Oliveira | I23: 351 | J23: Avenida Juscelino Kubitschek de Oliveira | K23: Campo Do Galvão | L23: Guaratinguetá | M23: SP | N23: 12505-300 | O23: THIAGO | P23: ERICSON | Q23: (12) 3128-3198 | R23: (12) 97403-3715 | S23: loja023@oscarcalcados.com.br | T23: gerente023@oscarcalcados.com.br | U23: 0.41666667 | V23: 0.91666667 | AG23: Produção | AJ23: Última validação: | AK23: =IFERROR(__xludf.DUMMYFUNCTION("""COMPUTED_VALUE"""),"50915875001830") -> 50915875001830
A24: 24 | B24: 024 - Stock Show Sjc | C24: Estoque Vale Comercio De Calcados Ltda | D24: 08.776.666/0001-48 | E24: Aberta | F24: Grupo Stock Show Sjc | G24: Grupo F8 | H24: Rua Sebastião Humel | I24: 301 | J24: Rua Sebastião Humel | K24: Centro | L24: São José Dos Campos | M24: SP | N24: 12210-200 | O24: LUIS AMERICO | P24: ERICSON | Q24: (12) 3925-0316 | R24: (12) 97411-4525 | S24: loja024@stockshow.com.br | T24: gerente024@stockshow.com.br | U24: 0.375 | V24: 0.79166667 | AG24: Produção | AJ24: Última validação: | AK24: =IFERROR(__xludf.DUMMYFUNCTION("""COMPUTED_VALUE"""),"08776666000148") -> 08776666000148
A25: 26 | B25: 026 - Vale Sul 2 | C25: Oscar Calcados Ltda | D25: 50.915.875/0010-82 | E25: Aberta | F25: Grupo Oscar Calçados | G25: Grupo F1 | H25: Avenida Andrômeda | I25: 227 | J25: Avenida Andrômeda | K25: Jardim Satélite | L25: São José Dos Campos | M25: SP | N25: 12230-000 | O25: PETERSON | P25: ERICSON | Q25: (12) 3935-4082 | R25: (12) 99114-8360 | S25: loja026@oscarcalcados.com.br | T25: gerente026@oscarcalcados.com.br | U25: 0.41666667 | V25: 0.91666667 | AG25: Produção | AJ25: Última validação: | AK25: =IFERROR(__xludf.DUMMYFUNCTION("""COMPUTED_VALUE"""),"50915875001082") -> 50915875001082
A26: 28 | B26: 028 - Taub Ct | C26: Oscar Calcados Ltda | D26: 50.915.875/0019-10 | E26: Aberta | F26: Grupo Oscar Calçados | G26: Grupo F1 | H26: Praça Dom Epaminondas | I26: 54 | J26: Praça Dom Epaminondas | K26: Centro | L26: Taubaté | M26: SP | N26: 12010-020 | O26: ESTEFAN | P26: ERICSON | Q26: (12) 3622-5762 | R26: (12) 97407-1208 | S26: loja028@oscarcalcados.com.br | T26: gerente028@oscarcalcados.com.br | U26: 0.375 | V26: 0.77083333 | AG26: Beta | AJ26: Última validação: | AK26: =IFERROR(__xludf.DUMMYFUNCTION("""COMPUTED_VALUE"""),"50915875001910") -> 50915875001910
A27: 30 | B27: 030 - E-Commerce | C27: Oscar Calçados Ltda | D27: 50.915.875/9999-62 | E27: Aberta | F27: Grupo Oscar Ecommerce | G27: Geral | H27: Rua Serra Do Parima | I27: 123 | K27: Jardim Anhembi | L27: São José Dos Campos | M27: SP | N27: 12235-210 | O27: BACKOFFICE | P27: RENAN | AG27: Produção | AK27: =IFERROR(__xludf.DUMMYFUNCTION("""COMPUTED_VALUE"""),"50915875999962") -> 50915875999962
A28: 31 | B28: 031 - Constantino Mogi | C28: Constantino Calcados E Acessorios Ltda | D28: 10.980.442/0001-03 | E28: Aberta | F28: Grupo Constantino | G28: Grupo F8 | H28: Avenida Vereador Narciso Yague Guimarães | I28: 1001 | J28: Avenida Vereador Narciso Yague Guimarães | K28: Jardim Armenia | L28: Mogi Das Cruzes | M28: SP | N28: 08780-500 | O28: MAURICIO | P28: ERICSON | Q28: (11) 4728-4396 | R28: (11) 94078-0983 | S28: loja031@lojasconstantino.com.br | T28: gerente031@lojasconstantino.com.br | U28: 0.41666667 | V28: 0.91666667 | AG28: Produção | AJ28: Última validação: | AK28: =IFERROR(__xludf.DUMMYFUNCTION("""COMPUTED_VALUE"""),"10980442000103") -> 10980442000103
A29: 32 | B29: 032 - Mogi Shopp | C29: Oscar Calcados Ltda | D29: 50.915.875/0020-54 | E29: Aberta | F29: Grupo Oscar Calçados | G29: Grupo F1 | H29: Avenida Vereador Narciso Yague Guimarães | I29: 1001 | J29: Avenida Vereador Narciso Yague Guimarães | K29: Jardim Armenia | L29: Mogi Das Cruzes | M29: SP | N29: 08780-500 | O29: MAURICIO | P29: ERICSON | Q29: (11) 4798-6553 | R29: (11) 94009-5981 | S29: loja032@oscarcalcados.com.br | T29: gerente032@oscarcalcados.com.br | U29: 0.41666667 | V29: 0.91666667 | AG29: Produção | AJ29: Última validação: | AK29: =IFERROR(__xludf.DUMMYFUNCTION("""COMPUTED_VALUE"""),"50915875002054") -> 50915875002054
A30: 33 | B30: 033 - Mogi Centro | C30: Hrc Comercio De Calcados Ltda | D30: 68.910.587/0001-00 | E30: Fechada | F30: Geral | G30: Grupo F7 | H30: Rua Doutor Paulo Frontin | I30: 161 | K30: Centro | L30: Mogi Das Cruzes | M30: SP | N30: 08710-050 | AG30: Produção | AK30: =IFERROR(__xludf.DUMMYFUNCTION("""COMPUTED_VALUE"""),"68910587000100") -> 68910587000100
A31: 34 | B31: 034 - Stock Show Bc | C31: Stock Bras Cubas Ltda | D31: 03.972.679/0001-79 | E31: Aberta | F31: Grupo Stock Show Mogi | G31: Grupo F8 | H31: Rua Francisco Afonso De Melo | I31: 135 | J31: Rua Francisco Afonso de Melo | K31: Vila Bras Cubas | L31: Mogi Das Cruzes | M31: SP | N31: 08740-310 | O31: ARTEMIS | P31: HELENA | Q31: (11) 4723-4359 | R31: (11) 34024-0939 | S31: loja034@stockshow.com.br | T31: gerente034@stockshow.com.br | U31: 0.41666667 | V31: 0.75 | AG31: Produção | AJ31: Última validação: | AK31: =IFERROR(__xludf.DUMMYFUNCTION("""COMPUTED_VALUE"""),"03972679000179") -> 03972679000179
A32: 35 | B32: 035 - Stock Show Sz | C32: Stock Show Suzano Ltda | D32: 04.431.428/0001-40 | E32: Aberta | F32: Grupo Stock Show Mogi | G32: Grupo F8 | H32: Rua Eliziel Alves Costa | I32: 34 | J32: Rua Eliziel Alves Costa | K32: Conjunto Residencial Ir | L32: Suzano | M32: SP | N32: 08673-110 | O32: ARTEMIS | P32: HELENA | Q32: (11) 4741-4895 | R32: (11) 94794-0416 | S32: loja035@stockshow.com.br | T32: gerente035@stockshow.com.br | U32: 0.39583333 | V32: 0.76388889 | AG32: Produção | AJ32: Última validação: | AK32: =IFERROR(__xludf.DUMMYFUNCTION("""COMPUTED_VALUE"""),"04431428000140") -> 04431428000140
A33: 36 | B33: 036 - Scarlen Shopp Suzan | C33: Scarlen Calcados Ltda | D33: 02.010.526/0001-88 | E33: Aberta | F33: Grupo Scarlen | G33: Grupo F8 | H33: Rua Sete De Setembro | I33: 555 | J33: Rua 7 de Setembro | K33: Parque Suzano | L33: Suzano | M33: SP | N33: 08673-020 | O33: ARTEMIS | P33: HELENA | Q33: (11) 4746-7062 | R33: (11) 94772-0433 | S33: loja036@scarlen.com.br | T33: gerente036@scarlen.com.br | U33: 0.41666667 | V33: 0.8125 | AG33: Produção | AJ33: Última validação: | AK33: =IFERROR(__xludf.DUMMYFUNCTION("""COMPUTED_VALUE"""),"02010526000188") -> 02010526000188
A34: 37 | B34: 037 - Scarlen Mogi Centro | C34: Helena Cazarine Calcados E Acessorios Ltda | D34: 58.760.141/0001-92 | E34: Aberta | F34: Grupo Scarlen | G34: Grupo F8 | H34: Rua Braz Cubas | I34: 171 | J34: Rua Brás Cubas | K34: Centro | L34: Mogi Das Cruzes | M34: SP | N34: 08710-410 | O34: ARTEMIS | P34: HELENA | Q34: (11) 4799-7262 | R34: (11) 94736-0495 | S34: loja037@scarlen.com.br | T34: gerente037@scarlen.com.br | U34: 0.39583333 | V34: 0.77083333 | AG34: Produção | AJ34: Última validação: | AK34: =IFERROR(__xludf.DUMMYFUNCTION("""COMPUTED_VALUE"""),"58760141000192") -> 58760141000192
A35: 38 | B35: 038 - Scarlen Mogi Shopp | C35: Cazarine & Constantino Ltda | D35: 67.109.132/0001-27 | E35: Aberta | F35: Grupo Scarlen | G35: Grupo F8 | H35: Avenida Vereador Narciso Yague Guimarães | I35: 1001 | J35: Av. Ver. Narciso Yague Guimarães, Arco: 230 | K35: Jardim Armenia | L35: Mogi Das Cruzes | M35: SP | N35: 08780-500 | O35: ARTEMIS | P35: HELENA | Q35: (11) 4798-6554 | R35: (11) 94738-0583 | S35: loja038@scarlen.com.br | T35: gerente038@scarlen.com.br | U35: 0.41666667 | V35: 0.91666667 | AG35: Produção | AJ35: Última validação: | AK35: =IFERROR(__xludf.DUMMYFUNCTION("""COMPUTED_VALUE"""),"67109132000127") -> 67109132000127
A36: 39 | B36: 039 - Cl Mg | C36: Oscar Calcados Ltda | D36: 50.915.875/0021-35 | E36: Aberta | F36: Grupo Oscar Calçados | G36: Grupo F1 | H36: Rua Doutor Deodato Wertheimer | I36: 1395 | J36: Rua Doutor Deodato Wertheimer | K36: Centro | L36: Mogi Das Cruzes | M36: SP | N36: 08710-430 | O36: MAURICIO | P36: ERICSON | Q36: (11) 4791-8982 | R36: (11) 97827-1541 | S36: loja039@oscarcalcados.com.br | T36: gerente039@oscarcalcados.com.br | U36: 0.375 | V36: 0.79166667 | AG36: Produção | AJ36: Última validação: | AK36: =IFERROR(__xludf.DUMMYFUNCTION("""COMPUTED_VALUE"""),"50915875002135") -> 50915875002135
A37: 40 | B37: 040 - Arezzo Shopp Mogi | C37: Ccrh Comercio De Calcados Ltda | D37: 02.163.422/0001-03 | E37: Aberta | F37: Grupo Arezzo | G37: Grupo F9 | H37: Avenida Vereador Narciso Yague Guimarães | I37: 1001 | J37: Av Ver. Narciso Yague Guimarães, loja 201 | K37: Jardim Armenia | L37: Mogi Das Cruzes | M37: SP | N37: 08780-500 | O37: ARTEMIS | P37: HELENA | Q37: (11) 4728-4395 | R37: (11) 91327-3036 | S37: loja040@lojasarezzo.com.br | T37: gerente040@lojasarezzo.com.br | U37: 0.41666667 | V37: 0.91666667 | AG37: Produção | AJ37: Última validação: | AK37: =IFERROR(__xludf.DUMMYFUNCTION("""COMPUTED_VALUE"""),"02163422000103") -> 02163422000103
A38: 41 | B38: 041 - Rio Preto Ct | C38: Oscar Calcados Ltda | D38: 50.915.875/0062-03 | E38: Aberta | F38: Grupo Oscar Calçados | G38: Grupo F1 | H38: Rua General Glicerio | I38: 2826 | J38: Rua General Glicério | K38: Centro | L38: Sao Jose Do Rio Preto | M38: SP | N38: 15015-400 | O38: ROGERS | P38: ERICSON | Q38: (17) 3519-3058 | R38: (17) 97400-5794 | S38: loja041@oscarcalcados.com.br | T38: gerente041@oscarcalcados.com.br | U38: 0.375 | V38: 0.79166667 | AG38: Produção | AJ38: Última validação: | AK38: =IFERROR(__xludf.DUMMYFUNCTION("""COMPUTED_VALUE"""),"50915875006203") -> 50915875006203
A39: 42 | B39: 042 - Stock Show Poá | C39: Francisco Telles Marcondes Neto | D39: 08.062.235/0001-10 | E39: Aberta | F39: Grupo Stock Show Mogi | G39: Grupo F8 | H39: Rua Silvério Pereira Jordão | I39: 37 | J39: Rua Silvério Pereira Jordão | K39: Centro | L39: Poá | M39: SP | N39: 08550-030 | O39: ARTEMIS | P39: HELENA | Q39: (11) 4634-4633 | R39: (11) 94029-0626 | S39: loja042@stockshow.com.br | T39: gerente042@stockshow.com.br | U39: 0.375 | V39: 0.75 | AG39: Produção | AJ39: Última validação: | AK39: =IFERROR(__xludf.DUMMYFUNCTION("""COMPUTED_VALUE"""),"08062235000110") -> 08062235000110
A40: 43 | B40: 043 - Suzano Shopp | C40: Oscar Calcados Ltda | D40: 50.915.875/0022-16 | E40: Aberta | F40: Grupo Oscar Calçados | G40: Grupo F1 | H40: Rua Sete De Setembro | I40: 555 | J40: Rua 7 de setembro, loja 115/116 | K40: Centro | L40: Suzano | M40: SP | N40: 08673-020 | O40: MAURICIO | P40: ERICSON | Q40: (11) 4742-3864 / (11) 4743-5094 | R40: (11) 94029-0796 | S40: loja043@oscarcalcados.com.br | T40: gerente043@oscarcalcados.com.br | U40: 0.41666667 | V40: 0.91666667 | AG40: Produção | AJ40: Última validação: | AK40: =IFERROR(__xludf.DUMMYFUNCTION("""COMPUTED_VALUE"""),"50915875002216") -> 50915875002216
...

Sheet 📊 RESUMO
B2: 📊 RESUMO GERENCIAL — LOJAS OSCAR
B4: Total de Lojas | C4: =COUNTA('CADASTRO LOJAS'!A3:A230) -> 228
B5: 🟢 Abertas | C5: =COUNTIF('CADASTRO LOJAS'!E3:E230,"Aberta") -> 205
B6: 🔴 Fechadas | C6: =COUNTIF('CADASTRO LOJAS'!E3:E230,"Fechada") -> 23
B7: ⚠️ A Verificar | C7: =COUNTIF('CADASTRO LOJAS'!E3:E230,"VERIFICAR") -> 0
B10: Lojas por Estado (UF) | E10: Lojas por Grupo Financeiro
B11: BA | C11: =COUNTIF('CADASTRO LOJAS'!M3:M230,"BA") -> 9 | E11: Geral | F11: =COUNTIF('CADASTRO LOJAS'!G3:G230,"Geral") -> 11
B12: CE | C12: =COUNTIF('CADASTRO LOJAS'!M3:M230,"CE") -> 9 | E12: Grupo Diad | F12: =COUNTIF('CADASTRO LOJAS'!G3:G230,"Grupo Diad") -> 4
B13: ES | C13: =COUNTIF('CADASTRO LOJAS'!M3:M230,"ES") -> 5 | E13: Grupo F1 | F13: =COUNTIF('CADASTRO LOJAS'!G3:G230,"Grupo F1") -> 59
B14: MG | C14: =COUNTIF('CADASTRO LOJAS'!M3:M230,"MG") -> 5 | E14: Grupo F10 | F14: =COUNTIF('CADASTRO LOJAS'!G3:G230,"Grupo F10") -> 19
B15: RJ | C15: =COUNTIF('CADASTRO LOJAS'!M3:M230,"RJ") -> 1 | E15: Grupo F2 | F15: =COUNTIF('CADASTRO LOJAS'!G3:G230,"Grupo F2") -> 2
B16: RS | C16: =COUNTIF('CADASTRO LOJAS'!M3:M230,"RS") -> 63 | E16: Grupo F3 | F16: =COUNTIF('CADASTRO LOJAS'!G3:G230,"Grupo F3") -> 26
B17: SC | C17: =COUNTIF('CADASTRO LOJAS'!M3:M230,"SC") -> 31 | E17: Grupo F4 | F17: =COUNTIF('CADASTRO LOJAS'!G3:G230,"Grupo F4") -> 67
B18: SP | C18: =COUNTIF('CADASTRO LOJAS'!M3:M230,"SP") -> 105 | E18: Grupo F5 | F18: =COUNTIF('CADASTRO LOJAS'!G3:G230,"Grupo F5") -> 3
E19: Grupo F6 | F19: =COUNTIF('CADASTRO LOJAS'!G3:G230,"Grupo F6") -> 2
E20: Grupo F7 | F20: =COUNTIF('CADASTRO LOJAS'!G3:G230,"Grupo F7") -> 11
B21: Lojas por Regional | E21: Grupo F8 | F21: =COUNTIF('CADASTRO LOJAS'!G3:G230,"Grupo F8") -> 9
B22: ARTEMIS | C22: =COUNTIF('CADASTRO LOJAS'!O3:O230,"ARTEMIS") -> 15 | E22: Grupo F9 | F22: =COUNTIF('CADASTRO LOJAS'!G3:G230,"Grupo F9") -> 15
B23: BACKOFFICE | C23: =COUNTIF('CADASTRO LOJAS'!O3:O230,"BACKOFFICE") -> 1
B24: BERNARDO | C24: =COUNTIF('CADASTRO LOJAS'!O3:O230,"BERNARDO") -> 23
B25: CLAUDIO | C25: =COUNTIF('CADASTRO LOJAS'!O3:O230,"CLAUDIO") -> 7
B26: CLOVIS | C26: =COUNTIF('CADASTRO LOJAS'!O3:O230,"CLOVIS") -> 20
B27: ESTEFAN | C27: =COUNTIF('CADASTRO LOJAS'!O3:O230,"ESTEFAN") -> 8
B28: JORGE | C28: =COUNTIF('CADASTRO LOJAS'!O3:O230,"JORGE") -> 17
B29: JOÃO PAULO | C29: =COUNTIF('CADASTRO LOJAS'!O3:O230,"JOÃO PAULO") -> 7
B30: KATIANE | C30: =COUNTIF('CADASTRO LOJAS'!O3:O230,"KATIANE") -> 6
B31: LOJA FECHADA | C31: =COUNTIF('CADASTRO LOJAS'!O3:O230,"LOJA FECHADA") -> 2
B32: LUIGI | C32: =COUNTIF('CADASTRO LOJAS'!O3:O230,"LUIGI") -> 6
B33: LUIS AMERICO | C33: =COUNTIF('CADASTRO LOJAS'!O3:O230,"LUIS AMERICO") -> 9
B34: MATRIZ | C34: =COUNTIF('CADASTRO LOJAS'!O3:O230,"MATRIZ") -> 1
B35: MAURICIO | C35: =COUNTIF('CADASTRO LOJAS'!O3:O230,"MAURICIO") -> 9
B36: PATRICIA | C36: =COUNTIF('CADASTRO LOJAS'!O3:O230,"PATRICIA") -> 23
B37: PETERSON | C37: =COUNTIF('CADASTRO LOJAS'!O3:O230,"PETERSON") -> 5
B38: RODRIGO | C38: =COUNTIF('CADASTRO LOJAS'!O3:O230,"RODRIGO") -> 7
B39: ROGERS | C39: =COUNTIF('CADASTRO LOJAS'!O3:O230,"ROGERS") -> 8
B40: SUILA | C40: =COUNTIF('CADASTRO LOJAS'!O3:O230,"SUILA") -> 2
B41: THIAGO | C41: =COUNTIF('CADASTRO LOJAS'!O3:O230,"THIAGO") -> 6
B42: VIVIANE | C42: =COUNTIF('CADASTRO LOJAS'!O3:O230,"VIVIANE") -> 4
B45: Lojas por Diretor
B46: CERUTTI | C46: =COUNTIF('CADASTRO LOJAS'!P3:P230,"CERUTTI") -> 90
...

Sheet DADOS_ORIGINAIS_Lojas
B1: Horarios de funcionamento
B2: Shopping | C2: segunda a sexta, 10:00–22:00 sabado, 10:00–22:00 Domingo, 12:00-20:00
B3: Lojas centro carioca | C3: segunda a sexta, 09:00–19:00 sabado, 09:00–13:00 (209 09:00-15:00)
B4: Lojas jo/oscar | C4: segunda a sexta, 11:00–19:00 sabado, 11:00–17:00
B5: Lojas jo/oscar | C5: segunda a sexta, 09:00–19:00 sabado, 09:00–17:00
A7: Status | B7: 46189.502 | C7: CEP | D7: Endereço | E7: Número | F7: Bairro / Distrito | G7: Cidade | H7: UF | I7: CNPJ | J7: Grupo | K7: Telefone | L7: Whatsapp | M7: Diretor | N7: Campo | O7: Taxa de deslocamento | P7: Hora de Abertura | Q7: Hora de Fechamento | R7: Email Loja | S7: Email Gerente | T7: Ultima Atualização | U7: 46044.429
A8: ABERTA | B8: 001 - Cl2 | C8: 12210260 | D8: Rua Sete de Setembro | E8: 344 | F8: Centro | G8: São José dos Campos | H8: SP | I8: 50.915.875/0012-44 | J8: Oscar Calçados | K8: (12) 3908-9009 | L8: 12 997409-3794 | M8: Ericson | N8: Oscar | O8: FALSE | P8: 0.375 | Q8: 0.79166667 | R8: loja001@oscarcalcados.com.br | S8: gerente001@oscarcalcados.com.br | T8: Última validação: | U8: 46044.7
A9: ABERTA | B9: 002 - Jp | C9: 12216000 | D9: Avenida Pedro Álvares Cabral | E9: 905 | F9: Jardim Paulista | G9: São José dos Campos | H9: SP | I9: 54.237.938/0001-59 | J9: Oscar Calçados | K9: (12) 3928-7884 | L9: 12 97402-0423 | M9: Ericson | O9: FALSE | P9: 0.375 | Q9: 0.79166667 | R9: loja002@oscarcalcados.com.br | S9: gerente002@oscarcalcados.com.br | T9: Última validação: | U9: 46044.701
A10: ABERTA | B10: 003 - Cl 1 | C10: 12210260 | D10: Rua Sete de Setembro | E10: 142 | F10: Centro | G10: São José dos Campos | H10: SP | I10: 50.915.875/0013-25 | J10: Oscar Calçados | K10: (12) 3909-1311 | L10: 12 97410-6235 | M10: Ericson | O10: FALSE | P10: 0.375 | Q10: 0.79166667 | R10: loja003@oscarcalcados.com.br | S10: gerente003@oscarcalcados.com.br | T10: Última validação: | U10: 46044.701
A11: ABERTA | B11: 004 - Oscar Calçados de Rua | C11: 12327320 | D11: Rua Sargento Acrísio Santana, 149 | E11: 149 | F11: Centro | G11: Jacareí | H11: SP | I11: 50.915.875/0014-06 | J11: Oscar Calçados | K11: (12) 3951-8988 | L11: 12 97406-6835 | M11: Ericson | O11: FALSE | P11: 0.375 | Q11: 0.79166667 | R11: loja004@oscarcalcados.com.br | S11: gerente004@oscarcalcados.com.br | T11: Última validação: | U11: 46105.637
A12: ABERTA | B12: 005 - Jc 1 | C12: 12308011 | D12: Praça Raul Chaves | E12: 79 | F12: Centro | G12: Jacareí | H12: SP | I12: 72.014.681/0001-58 | J12: Oscar Calçados | K12: (12) 3954-0797 | L12: 12 97406-7534 | M12: Ericson | O12: FALSE | P12: 0.375 | Q12: 0.79166667 | R12: loja005@oscarcalcados.com.br | S12: gerente005@oscarcalcados.com.br | T12: Última validação: | U12: 46077.435
A13: ABERTA | B13: 006 - Sh 2 | C13: 12215900 | D13: Avenida Deputado Benedito Matarazzo | E13: 9403 | F13: Jardim Paulista | G13: São José dos Campos | H13: SP | I13: 50.915.875/0004-34 | J13: Oscar Calçados | K13: (12) 3924-3420 | L13: 12 97408-3216 | M13: Ericson | O13: FALSE | P13: 0.41666667 | Q13: 0.91666667 | R13: loja006@oscarcalcados.com.br | S13: gerente006@oscarcalcados.com.br | T13: Última validação: | U13: 46044.702
A14: ABERTA | B14: 007 - Cn | C14: 12242000 | D14: Avenida São João | E14: 2200 | F14: Jardim das Colinas | G14: São José dos Campos | H14: SP | I14: 50.915.875/0003-53 | J14: Oscar Calçados | K14: (12) 3924-3432 | L14: 12 97411-7843 | M14: Ericson | O14: FALSE | P14: 0.41666667 | Q14: 0.91666667 | R14: loja007@oscarcalcados.com.br | S14: gerente007@oscarcalcados.com.br | T14: Última validação: | U14: 46044.703
A15: ABERTA | B15: 008 - Rio Preto Shopp | C15: 15090000 | D15: Avenida Brigadeiro Faria Lima | E15: 6363 | F15: Vila São José | G15: São José do Rio Preto | H15: SP | I15: 48.973.705/0013-55 | J15: Oscar Calçados | K15: (17) 3201-2923 | L15: 17 97400-8780 | M15: Ericson | O15: FALSE | P15: 0.41666667 | Q15: 0.91666667 | R15: loja008@oscarcalcados.com.br | S15: gerente008@oscarcalcados.com.br | T15: Última validação: | U15: 46044.703
A16: ABERTA | B16: 009 - Oscar Jd.Satélite | C16: 12230001 | D16: Av. Andrômeda, 1868 | E16: 1868 | F16: Jd. Satélite | G16: São José dos Campos | H16: SP | I16: 50.915.875/0001-91 | J16: Oscar Calçados | K16: (12) 3932-0066 | L16: 12 97404-1272 | M16: Ericson | O16: FALSE | P16: 0.375 | Q16: 0.79166667 | R16: loja009@oscarcalcados.com.br | S16: gerente009@oscarcalcados.com.br | T16: Última validação: | U16: 46044.437
A17: ABERTA | B17: 011 Arezzo Vale Sul | C17: 12230000 | D17: Av. Andrômeda, 227 - Loja 204 | E17: 227 | F17: Jd. Satélite | G17: São José dos Campos | H17: SP | I17: 09.108.526/0001-64 | J17: Arezzo | K17: (12) 3935-4056 | L17: 12 97411-6754 | M17: Sonia | O17: FALSE | P17: 0.41666667 | Q17: 0.91666667 | R17: loja011@lojasarezzo.com.br | S17: gerente011@lojasarezzo.com.br | T17: Última validação: | U17: 46044.704
A18: ABERTA | B18: 012 - Arezzo Center Vale | C18: 12216580 | D18: Av. Dep. Benedito Matarazzo, 9403 Loja S/113 | E18: 9403 | F18: Jd. Oswaldo Cruz | G18: São José dos Campos | H18: SP | I18: 02.139.784/0001-69 | J18: Arezzo | K18: (12) 3947-7619 | L18: 12 97404-4892 | M18: Sonia | O18: FALSE | P18: 0.41666667 | Q18: 0.91666667 | R18: loja012@lojasarezzo.com.br | S18: gerente012@lojasarezzo.com.br | T18: Última validação: | U18: 46044.704
A19: ABERTA | B19: 013 - Arezzo CN | C19: 12242970 | D19: São João, 2200 lj. Nº 010/011 | E19: 2200 | F19: Jd. das Colinas | G19: São José dos Campos | H19: SP | I19: 08.371.232/0001-68 | J19: Arezzo | K19: (12) 3904-7850 | L19: 12 97411-5572 | M19: Sonia | O19: FALSE | P19: 0.41666667 | Q19: 0.91666667 | R19: loja013@lojasarezzo.com.br | S19: gerente013@lojasarezzo.com.br | T19: Última validação: | U19: 46044.704
A20: ABERTA | B20: 015 - Victor Hugo CV | C20: 12216580 | D20: Av. Dep. Benedito Matarazzo, lj 509/10 | E20: 9403 | F20: Jd. Oswaldo Cruz | G20: São José dos Campos | H20: SP | I20: 04.723.248/0001-31 | J20: Victor Hugo | K20: (12) 3928-7895 | L20: 12 97407-7463 | M20: Sonia | O20: FALSE | P20: 0.41666667 | Q20: 0.91666667 | R20: centervale@victorhugo.com.br | T20: Última validação: | U20: 46105.664
A21: ABERTA | B21: 016 - Guara Ct | C21: 12500150 | D21: Rua Comendador João Galvão | E21: 36 | F21: Centro | G21: Guaratinguetá | H21: SP | I21: 50.915.875/0015-97 | J21: Oscar Calçados | K21: (12) 3128-3197 | L21: 12 97411-1083 | M21: Ericson | O21: FALSE | P21: 0.375 | Q21: 0.79166667 | R21: loja016@oscarcalcados.com.br | S21: gerente016@oscarcalcados.com.br | T21: Última validação: | U21: 46044.705
A22: ABERTA | B22: 017 - Tênis VS | C22: 12230000 | D22: Avenida Andrômeda | E22: 227 | F22: Jardim Satélite | G22: São José dos Campos | H22: SP | I22: 05.574.086/0001-80 | J22: Oscar Calçados | K22: (12) 3935-4063 | L22: 12 97402-7510 | M22: Ericson | O22: FALSE | P22: 0.41666667 | Q22: 0.91666667 | R22: loja017@oscarcalcados.com.br | S22: gerente017@oscarcalcados.com.br | T22: Última validação: | U22: 46044.705
A23: ABERTA | B23: 018 - Arezzo - Shopping | C23: 12308001 | D23: Rua Barão de Jacareí, 364 lj. 23 | E23: 364 | F23: Centro | G23: Jacareí | H23: SP | I23: 14.620.014/0001-12 | J23: Arezzo | K23: (12) 3954-8385 | L23: 12 97411-3673 | M23: Sonia | O23: FALSE | P23: 0.41666667 | Q23: 0.91666667 | R23: loja018@lojasarezzo.com.br | S23: gerente018@lojasarezzo.com.br | T23: Última validação: | U23: 46044.705
A24: ABERTA | B24: 019 - Jc Sh | C24: 12308001 | D24: Rua Barão de Jacareí | E24: 364 | F24: Centro | G24: Jacareí | H24: SP | I24: 50.915.875/0016-78 | J24: Oscar Calçados | K24: (12) 3955-9599 | L24: 12 97411-7172 | M24: Ericson | O24: FALSE | P24: 0.41666667 | Q24: 0.91666667 | R24: loja019@oscarcalcados.com.br | S24: gerente019@oscarcalcados.com.br | T24: Última validação: | U24: 46044.706
A25: ABERTA | B25: 020 - Taub Shopp | C25: 12050181 | D25: Avenida Charles Schnneider | E25: 1700 | F25: Vila Costa | G25: Taubaté | H25: SP | I25: 50.915.875/0017-54 | J25: Oscar Calçados | K25: (12) 3634-3637 | L25: 12 97411-5917 | M25: Ericson | O25: FALSE | P25: 0.41666667 | Q25: 0.91666667 | R25: loja020@oscarcalcados.com.br | S25: gerente020@oscarcalcados.com.br | T25: Última validação: | U25: 46044.706
A26: ABERTA | B26: 022 - Tenis Calçadão | C26: 12210260 | D26: Rua Sete de Setembro | E26: 156 | F26: Centro | G26: São José dos Campos | H26: SP | I26: 05.908.530/0001-59 | J26: Oscar Calçados | K26: (12) 3908-9006 | L26: 12 97411-1976 | M26: Ericson | O26: FALSE | P26: 0.375 | Q26: 0.79166667 | R26: loja022@oscarcalcados.com.br | S26: gerente022@oscarcalcados.com.br | T26: Última validação: | U26: 46044.706
A27: ABERTA | B27: 023 - Guará Shopp | C27: 12505300 | D27: Avenida Juscelino Kubitschek de Oliveira | E27: 351 | F27: Campo do Galvão | G27: Guaratinguetá | H27: SP | I27: 50.915.875/0018-30 | J27: Oscar Calçados | K27: (12) 3128-3198 | L27: 12 97403-3715 | M27: Ericson | O27: FALSE | P27: 0.41666667 | Q27: 0.91666667 | R27: loja023@oscarcalcados.com.br | S27: gerente023@oscarcalcados.com.br | T27: Última validação: | U27: 46044.707
A28: ABERTA | B28: 024 - Stock Show | C28: 12210200 | D28: Rua Sebastião Humel | E28: 301 | F28: Centro | G28: São José dos Campos | H28: SP | I28: 08.776.666/0001-48 | J28: Grupo Stock Show SJC | K28: (12) 3925-0316 | L28: 12 97411-4525 | M28: Ericson | O28: FALSE | P28: 0.375 | Q28: 0.79166667 | R28: loja024@stockshow.com.br | S28: gerente024@stockshow.com.br | T28: Última validação: | U28: 46106.413
A29: ABERTA | B29: 026 - Vale Sul 2 | C29: 12230000 | D29: Avenida Andrômeda | E29: 227 | F29: Jardim Satélite | G29: São José dos Campos | H29: SP | I29: 50.915.875/0010-82 | J29: Oscar Calçados | K29: (12) 3935-4082 | L29: 12 99114-8360 | M29: Ericson | O29: FALSE | P29: 0.41666667 | Q29: 0.91666667 | R29: loja026@oscarcalcados.com.br | S29: gerente026@oscarcalcados.com.br | T29: Última validação: | U29: 46112.524
A30: ABERTA | B30: 028 - Taubaté | C30: 12010020 | D30: Praça Dom Epaminondas | E30: 54 | F30: Centro | G30: Taubaté | H30: SP | I30: 50.915.875/0019-10 | J30: Oscar Calçados | K30: (12) 3622-5762 | L30: (12) 97407-1208 | M30: Ericson | O30: FALSE | P30: 0.375 | Q30: 0.77083333 | R30: loja028@oscarcalcados.com.br | S30: gerente028@oscarcalcados.com.br | T30: Última validação: | U30: 46106.425
A31: ABERTA | B31: 031 - Constantino Mogi | C31: 08780500 | D31: Avenida Vereador Narciso Yague Guimarães | E31: 1001 | F31: Jardim Armênia | G31: Mogi das Cruzes | H31: SP | I31: 10.980.442/0001-03 | J31: Constantino | K31: (11) 4728-4396 | L31: 11 94078-0983 | M31: Ericson | O31: FALSE | P31: 0.41666667 | Q31: 0.91666667 | R31: loja031@lojasconstantino.com.br | S31: gerente031@lojasconstantino.com.br | T31: Última validação: | U31: 46044.707
A32: ABERTA | B32: 032 - Mogi Shopp | C32: 08780000 | D32: Avenida Vereador Narciso Yague Guimarães | E32: 1001 | F32: Centro Cívico | G32: Mogi das Cruzes | H32: SP | I32: 50.915.875/0020-54 | J32: Oscar Calçados | K32: (11) 4798-6553 | L32: 11 94009-5981 | M32: Ericson | O32: FALSE | P32: 0.41666667 | Q32: 0.91666667 | R32: loja032@oscarcalcados.com.br | S32: gerente032@oscarcalcados.com.br | T32: Última validação: | U32: 46044.732
... A44: ABERTA | B44: 045 - Araçatuba | C44: 16010300 | D44: Rua Marechal Deodoro | E44: 139 | F44: Centro | G44: Araçatuba | H44: SP | I44: 48.973.705/0010-02 | J44: Oscar Calçados | K44: (18) 3607-2278 | L44: 18 97400-4018 | M44: Ericson | O44: FALSE | P44: 0.375 | Q44: 0.79166667 | R44: loja045@oscarcalcados.com.br | S44: gerente045@oscarcalcados.com.br | T44: Última validação: | U44: 46044.735
A45: FECHADA | B45: 046 - Constantino SJC | C45: 12215900 | D45: Avenida Deputado Benedito Matarazzo | E45: 9403 | F45: Jardim Paulista | G45: São José dos Campos | H45: SP | I45: 09.332.225/0001-10 | J45: Constantino | K45: (12) 3928-7871 | O45: FALSE | R45: constantino46@lojasconstantino.com.br | T45: Última validação: | U45: 46045.735
A46: ABERTA | B46: 047 - Pinda Shopp | C46: 12421705 | D46: Rua Alcides Ramos Nogueira | E46: 650 | F46: Nossa Senhora do Perpétuo Socorro | G46: Pindamonhangaba | H46: SP | I46: 19.853.593/0001-67 | J46: Oscar Calçados | K46: (12) 3644-1797 | L46: 12 97411-7551 | M46: Ericson | O46: FALSE | P46: 0.41666667 | Q46: 0.91666667 | R46: loja047@oscarcalcados.com.br | S46: gerente047@oscarcalcados.com.br | T46: Última validação: | U46: 46044.734
A47: ABERTA | B47: 048 - Pinda Ct | C47: 12400470 | D47: Praça Monsenhor Marcondes | E47: 50 | F47: Centro | G47: Pindamonhangaba | H47: SP | I47: 50.915.875/0023-05 | J47: Oscar Calçados | K47: (12) 3644-1119 | L47: 12 97411-2318 | M47: Ericson | O47: FALSE | P47: 0.375 | Q47: 0.79166667 | R47: loja048@oscarcalcados.com.br | S47: gerente048@oscarcalcados.com.br | T47: Última validação: | U47: 46044.735
A48: ABERTA | B48: 049 - Lorena | C48: 12600005 | D48: Rua Doutor Rodrigues de Azevedo | E48: 240 | F48: Centro | G48: Lorena | H48: SP | I48: 50.915.875/0024-88 | J48: Oscar Calçados | K48: (12) 3159-1169 | L48: 12 97411-7364 | M48: Ericson | O48: FALSE | P48: 0.375 | Q48: 0.79166667 | R48: loja049@oscarcalcados.com.br | S48: gerente049@oscarcalcados.com.br | T48: Última validação: | U48: 46044.736
A49: ABERTA | B49: 050 - Victor Hugo Colinas | C49: 12242-000 | D49: Avenida São João, Lj 73/74/75 | E49: 2200 | F49: Jardim das Colinas | G49: São José dos Campos | H49: SP | I49: 21.400.535/0001-20 | J49: Grupo Victor Hugo | K49: (12) 3904-3540 | L49: 12 97411-9148 | M49: Sonia | O49: FALSE | P49: 0.41666667 | Q49: 0.91666667 | T49: Última validação: | U49: 46106.502
A50: ABERTA | B50: 053 - Bauru Shopping | C50: 17011900 | D50: Rua Henrique Savi | E50: 55 | F50: Vila Cidade Universitária | G50: Bauru | H50: SP | I50: 45.151.240/0001-25 | J50: Oscar Calçados | K50: (14) 3104-0511 | L50: 17 97400-0340 | M50: Ericson | O50: FALSE | P50: 0.41666667 | Q50: 0.91666667 | R50: loja053@oscarcalcados.com.br | S50: gerente053@oscarcalcados.com.br | T50: Última validação: | U50: 46044.736
A51: ABERTA | B51: 054 - Ribeirão Preto | C51: 14010080 | D51: Rua Álvares Cabral | E51: 470 | F51: Centro | G51: Ribeirão Preto | H51: SP | I51: 48.973.705/0026-70 | J51: Oscar Calçados | K51: (16) 3519-3389 | L51: 16 97400-2273 | M51: Ericson | O51: FALSE | P51: 0.375 | Q51: 0.79166667 | R51: loja054@oscarcalcados.com.br | S51: gerente054@oscarcalcados.com.br | T51: Última validação: | U51: 46044.737
A52: ABERTA | B52: 055 - Usaflex Mogi Shopping | C52: 08780-910 | D52: Av Ver Narciso Yague Guimarães, lj 313 | E52: 1001 | F52: Jd Armênia | G52: Mogi das Cruzes | H52: SP | I52: 31.795.183/0001-02 | J52: Grupo Usaflex | K52: (11) 4728-7190 | L52: 11 97600-4756 | M52: Helena | O52: FALSE | P52: 0.41666667 | Q52: 0.91666667 | R52: mogishopping@usaflexfranquias.com.br | T52: Última validação: | U52: 46164.633
...

Sheet DADOS_ORIGINAIS_Dim
B2: idestabelecimento | C2: ds_status | D2: nm_razaosocial | E2: nm_nomefantasia | F2: num_cnpj | G2: num_inscricaoestadual | H2: nk_idunidadenegocio | I2: ds_sigla | J2: num_cep | K2: ds_uf | L2: ds_localidade | M2: ds_bairro | N2: num_numero | O2: ds_logradouro | P2: ds_rua_shop | Q2: loja_importante | R2: ds_unidadenegocio | S2: ds_bandeira | T2: grupo_financeiro | U2: diretor | V2: regional | W2: status_funcionamento_loja | X2: ds_varejo | Y2: metragem | Z2: email_loja
B3: 2 | C3: A | D3: Oscar Calcados Ltda | E3: 001 - Cl2 | F3: 50915875001244 | G3: 125566611110 | H3: 15 | I3: 1 | J3: 12210260 | K3: SP | L3: São José Dos Campos | M3: Centro | N3: 344 | O3: Rua Sete De Setembro | P3: Rua | Q3: S | R3: Grupo Oscar Calçados | S3: Grupo Oscar Calçados | T3: Grupo F1 | U3: ERICSON | V3: LUIS AMERICO | W3: Aberta | X3: Varejo Oscar | Y3: 550 | Z3: loja001@oscarcalcados.com.br
B4: 3 | C4: A | D4: E N Constantino Calcados Eireli | E4: 002 - Jp | F4: 54237938000159 | G4: 645132611118 | H4: 15 | I4: 2 | J4: 12216000 | K4: SP | L4: São José Dos Campos | M4: Jardim Paulista | N4: 905 | O4: Avenida Pedro Álvares Cabral | P4: Rua | Q4: N | R4: Grupo Oscar Calçados | S4: Grupo Oscar Calçados | T4: Grupo F7 | U4: ERICSON | V4: LUIS AMERICO | W4: Aberta | X4: Varejo Oscar | Y4: 222 | Z4: loja002@oscarcalcados.com.br
B5: 7 | C5: A | D5: Oscar Calcados Ltda | E5: 003 - Cl 1 | F5: 50915875001325 | G5: 125566630116 | H5: 15 | I5: 3 | J5: 12210260 | K5: SP | L5: São José Dos Campos | M5: Centro | N5: 142 | O5: Rua Sete De Setembro | P5: Rua | Q5: S | R5: Grupo Oscar Calçados | S5: Grupo Oscar Calçados | T5: Grupo F1 | U5: ERICSON | V5: LUIS AMERICO | W5: Aberta | X5: Varejo Oscar | Y5: 380 | Z5: loja003@oscarcalcados.com.br
B6: 8 | C6: A | D6: Oscar Calcados Ltda | E6: 004 - Jc 2 | F6: 50915875001406 | G6: 392.478.396.111 | H6: 15 | I6: 4 | J6: 12327320 | K6: SP | L6: Jacareí | M6: Centro | N6: 141 | O6: Rua Sargento Acrísio Santana | P6: Rua | Q6: S | R6: Grupo Oscar Calçados | S6: Grupo Oscar Calçados | T6: Grupo F1 | U6: ERICSON | V6: MAURICIO | W6: Aberta | X6: Varejo Oscar | Y6: 496 | Z6: loja004@oscarcalcados.com.br
B7: 11 | C7: A | D7: Racso Calcados Ltda | E7: 005 - Jc 1 | F7: 72014681000158 | G7: 392073624114 | H7: 15 | I7: 5 | J7: 12308011 | K7: SP | L7: Jacareí | M7: Centro | N7: 79 | O7: Praça Raul Chaves | P7: Rua | Q7: N | R7: Grupo Oscar Calçados | S7: Grupo Oscar Calçados | T7: Grupo F7 | U7: ERICSON | V7: MAURICIO | W7: Aberta | X7: Varejo Oscar | Y7: 184 | Z7: loja005@oscarcalcados.com.br
B8: 17 | C8: A | D8: Oscar Calcados Ltda | E8: 006 - Sh 2 | F8: 50915875000434 | G8: 645278848113 | H8: 15 | I8: 6 | J8: 12215900 | K8: SP | L8: São José Dos Campos | M8: Jardim Oswaldo Cruz | N8: 9403 | O8: Avenida Deputado Benedito Matarazzo | P8: Shopping | Q8: S | R8: Grupo Oscar Calçados | S8: Grupo Oscar Calçados | T8: Grupo F1 | U8: ERICSON | V8: LUIS AMERICO | W8: Aberta | X8: Varejo Oscar | Y8: 519 | Z8: loja006@oscarcalcados.com.br
B9: 12 | C9: A | D9: Oscar Calcados Ltda | E9: 007 - Cn | F9: 50915875000353 | G9: 645250010111 | H9: 15 | I9: 7 | J9: 12242000 | K9: SP | L9: São José Dos Campos | M9: Jardim Das Colinas | N9: 2200 | O9: Avenida São João | P9: Shopping | Q9: N | R9: Grupo Oscar Calçados | S9: Grupo Oscar Calçados | T9: Grupo F1 | U9: ERICSON | V9: PETERSON | W9: Aberta | X9: Varejo Oscar | Y9: 191 | Z9: loja007@oscarcalcados.com.br
B10: 177 | C10: A | D10: Oscar Calcados Ltda | E10: 008 - Rio Preto Shopp | F10: 50915875004421 | G10: 160.078.052.110 | H10: 15 | I10: 8 | J10: 15090000 | K10: SP | L10: Sao Jose Do Rio Preto | M10: Vila Sao Jose | N10: 6363 | O10: Avenida Brigadeiro Faria Lima | P10: Shopping | Q10: S | R10: Grupo Oscar Calçados | S10: Grupo Oscar Calçados | T10: Grupo F1 | U10: ERICSON | V10: ROGERS | W10: Aberta | X10: Varejo Oscar | Y10: 215 | Z10: loja008@oscarcalcados.com.br
B11: 13 | C11: A | D11: Oscar Calcados Ltda | E11: 009 - Js | F11: 50915875000191 | G11: 645074462117 | H11: 15 | I11: 9 | J11: 12230001 | K11: SP | L11: São José Dos Campos | M11: Jardim Satélite | N11: 1868 | O11: Avenida Andrômeda | P11: Rua | Q11: N | R11: Grupo Oscar Calçados | S11: Grupo Oscar Calçados | T11: Grupo F1 | U11: ERICSON | V11: PETERSON | W11: Aberta | X11: Varejo Oscar | Y11: 312 | Z11: loja009@oscarcalcados.com.br
B12: 14 | C12: A | D12: Oscar Calcados Ltda | E12: 010 - Cd Oscar | F12: 50915875000515 | G12: 645276604117 | H12: 15 | I12: 10 | J12: 12231010 | K12: SP | L12: São José Dos Campos | M12: Vila Nair | N12: 1692 | O12: Rua Paraibuna | Q12: N | R12: Grupo Oscar Calçados | S12: Grupo Oscar Calçados | T12: Grupo F1 | U12: RENAN | V12: LOJA FECHADA | W12: Aberta | X12: Varejo Oscar | Y12: 1
B13: 74 | C13: A | D13: Avs Comercio De Calcados Ltda | E13: 011 - Arezzo Vale Sul Shopp | F13: 9108526000164 | G13: 645514852111 | H13: 3 | I13: 11 | J13: 12230001 | K13: SP | L13: Sao Jose Dos Campos | M13: Jardim Satelite | N13: 227 | O13: Avenida Andromeda | P13: Shopping | Q13: N | R13: Grupo Arezzo | S13: Grupo Arezzo | T13: Grupo F9 | U13: SONIA | V13: VIVIANE | W13: Aberta | X13: Demais Bandeiras
B14: 19 | C14: A | D14: R Constantino Calcados Ltda | E14: 012 - Arezzo Center Vale | F14: 2139784000169 | G14: 645257479118 | H14: 3 | I14: 12 | J14: 12216580 | K14: SP | L14: Sao Jose Dos Campos | M14: Jardim Oswaldo Cruz | N14: 9403 | O14: Avenida Deputado Benedito Matarazzo | P14: Shopping | Q14: N | R14: Grupo Arezzo | S14: Grupo Arezzo | T14: Grupo F9 | U14: SONIA | V14: VIVIANE | W14: Aberta | X14: Demais Bandeiras
B15: 20 | C15: A | D15: Ofs Comercio De Calcados Ltda | E15: 013 - Arezzo Shopp Colinas | F15: 8371232000168 | G15: 645493846115 | H15: 3 | I15: 13 | J15: 12242000 | K15: SP | L15: São José Dos Campos | M15: Jardim Das Colinas | N15: 2200 | O15: Avenida São João | P15: Shopping | Q15: N | R15: Grupo Arezzo | S15: Grupo Arezzo | T15: Grupo F9 | U15: SONIA | V15: VIVIANE | W15: Aberta | X15: Demais Bandeiras
B16: 28 | C16: C | D16: Enac Calçados Ltda | E16: Ñ 014 - Schutz | F16: 4356327000151 | G16: 645420166116 | H16: 23 | I16: 14 | J16: 12215000 | K16: SP | L16: São José Dos Campos | M16: Monte Castelo | N16: 9403 | O16: Avenida Brasil | R16: Ñ Grupo Schutz | S16: Ñ Grupo Schutz | T16: Geral | W16: Fechada | X16: Demais Bandeiras
B17: 21 | C17: A | D17: Iacr Comercial Ltda | E17: 015 - Victor Hugo Cv | F17: 4723248000131 | G17: 645428618119 | H17: 5 | I17: 15 | J17: 12216580 | K17: SP | L17: São José Dos Campos | M17: Jardim Oswaldo Cruz | N17: 9403 | O17: Avenida Deputado Benedito Matarazzo | R17: Grupo Victor Hugo | S17: Grupo Victor Hugo | T17: Grupo F9 | U17: SONIA | V17: SUILA | W17: Aberta | X17: Demais Bandeiras
B18: 15 | C18: A | D18: Oscar Calcados Ltda | E18: 016 - Guara Ct | F18: 50915875001597 | G18: 332.292.808.114 | H18: 15 | I18: 16 | J18: 12500150 | K18: SP | L18: Guaratinguetá | M18: Centro | N18: 36 | O18: Rua Comendador João Galvão | P18: Rua | Q18: N | R18: Grupo Oscar Calçados | S18: Grupo Oscar Calçados | T18: Grupo F1 | U18: ERICSON | V18: THIAGO | W18: Aberta | X18: Varejo Oscar | Y18: 293 | Z18: loja016@oscarcalcados.com.br
B19: 16 | C19: A | D19: Vsc Calcados Ltda | E19: 017 - Tênis Vs | F19: 5574086000180 | G19: 645447055111 | H19: 15 | I19: 17 | J19: 12230000 | K19: SP | L19: São José Dos Campos | M19: Jardim Satélite | N19: 227 | O19: Avenida Andrômeda | P19: Shopping | Q19: N | R19: Grupo Oscar Calçados | S19: Grupo Oscar Calçados | T19: Grupo F7 | U19: ERICSON | V19: PETERSON | W19: Aberta | X19: Varejo Oscar | Y19: 89 | Z19: loja017@oscarcalcados.com.br
B20: 22 | C20: A | D20: Arsj Comercio De Calcados Ltda | E20: 018 - Arezzo Jacarei Shopp | F20: 14620014000112 | G20: 392.119.466.111 | H20: 3 | I20: 18 | J20: 12308001 | K20: SP | L20: Jacareí | M20: Centro | N20: 364 | O20: Rua Barão De Jacareí | P20: Shopping | Q20: N | R20: Grupo Arezzo | S20: Grupo Arezzo | T20: Grupo F9 | U20: SONIA | V20: VIVIANE | W20: Aberta | X20: Demais Bandeiras
B21: 24 | C21: A | D21: Oscar Calcados Ltda | E21: 019 - Jc Sh | F21: 50915875001678 | G21: 392478401118 | H21: 15 | I21: 19 | J21: 12308001 | K21: SP | L21: Jacareí | M21: Centro | N21: 364 | O21: Rua Barão De Jacareí | P21: Shopping | Q21: S | R21: Grupo Oscar Calçados | S21: Grupo Oscar Calçados | T21: Grupo F1 | U21: ERICSON | V21: MAURICIO | W21: Aberta | X21: Varejo Oscar | Y21: 219 | Z21: loja019@oscarcalcados.com.br
B22: 25 | C22: A | D22: Oscar Calcados Ltda | E22: 020 - Taub Shopp | F22: 50915875001759 | G22: 688713174114 | H22: 15 | I22: 20 | J22: 12040900 | K22: SP | L22: Taubaté | M22: Parque Senhor Do Bonfim | N22: 1700 | O22: Avenida Charles Schnneider | P22: Shopping | Q22: S | R22: Grupo Oscar Calçados | S22: Grupo Oscar Calçados | T22: Grupo F1 | U22: ERICSON | V22: ESTEFAN | W22: Aberta | X22: Varejo Oscar | Y22: 289 | Z22: loja020@oscarcalcados.com.br
B23: 26 | C23: C | D23: Co Comercio De Confecções Ltda | E23: Ñ 021 - Tenis Guará Shopp | F23: 6894399000188 | G23: 688242126113 | H23: 15 | I23: 21 | J23: 12505300 | K23: SP | L23: Guaratinguetá | M23: Campo Do Galvão | N23: 351 | O23: Avenida Juscelino Kubitschek De Oliveira | R23: Grupo Oscar Calçados | S23: Grupo Oscar Calçados | T23: Geral | W23: Fechada | X23: Varejo Oscar
B24: 27 | C24: A | D24: Jsc Comercio De Calcados Ltda | E24: 022 - Tenis Calçadão | F24: 5908530000156 | G24: 645473951112 | H24: 15 | I24: 22 | J24: 12210260 | K24: SP | L24: São José Dos Campos | M24: Centro | N24: 156 | O24: Rua Sete De Setembro | P24: Rua | Q24: N | R24: Grupo Oscar Calçados | S24: Grupo Oscar Calçados | T24: Grupo F7 | U24: ERICSON | V24: LUIS AMERICO | W24: Fechada | X24: Varejo Oscar | Y24: 166 | Z24: loja022@oscarcalcados.com.br
B25: 30 | C25: A | D25: Oscar Calcados Ltda | E25: 023 - Guará Shopp | F25: 50915875001830 | G25: 332292817115 | H25: 15 | I25: 23 | J25: 12505300 | K25: SP | L25: Guaratinguetá | M25: Campo Do Galvão | N25: 351 | O25: Avenida Juscelino Kubitschek De Oliveira | P25: Shopping | Q25: S | R25: Grupo Oscar Calçados | S25: Grupo Oscar Calçados | T25: Grupo F1 | U25: ERICSON | V25: THIAGO | W25: Aberta | X25: Varejo Oscar | Y25: 249 | Z25: loja023@oscarcalcados.com.br
B26: 54 | C26: A | D26: Estoque Vale Comercio De Calcados Ltda | E26: 024 - Stock Show Sjc | F26: 8776666000148 | G26: 645504778110 | H26: 10 | I26: 24 | J26: 12210200 | K26: SP | L26: São José Dos Campos | M26: Centro | N26: 301 | O26: Rua Sebastião Humel | P26: Rua | Q26: N | R26: Grupo Stock Show Sjc | S26: Grupo Stock Show Sjc | T26: Grupo F8 | U26: ERICSON | V26: LUIS AMERICO | W26: Aberta | X26: Demais Bandeiras | Y26: 381
B27: 56 | C27: C | D27: New Stock Jac Comercio De Calçados Ltda Epp | E27: Ñ 025 - Stock Show Jacarei | F27: 8919315000149 | G27: 392.233.533-117 | H27: 10 | I27: 25 | J27: 12327280 | K27: SP | L27: Jacareí | M27: Centro | N27: 165 | O27: Rua Coronel Carlos Porto | R27: Grupo Stock Show Sjc | S27: Grupo Stock Show Sjc | T27: Geral | W27: Fechada | X27: Demais Bandeiras
B28: 72 | C28: A | D28: Oscar Calcados Ltda | E28: 026 - Vale Sul 2 | F28: 50915875001082 | G28: 125007695113 | H28: 15 | I28: 26 | J28: 12230000 | K28: SP | L28: São José Dos Campos | M28: Jardim Satélite | N28: 227 | O28: Avenida Andrômeda | P28: Shopping | Q28: S | R28: Grupo Oscar Calçados | S28: Grupo Oscar Calçados | T28: Grupo F1 | U28: ERICSON | V28: PETERSON | W28: Aberta | X28: Varejo Oscar | Y28: 690 | Z28: loja026@oscarcalcados.com.br
B29: 75 | C29: C | D29: Col Calçados Ltda Epp | E29: Ñ 027 - Adidas Vs | F29: 6948876000140 | G29: 645514124117 | H29: 44 | I29: 27 | J29: 12230001 | K29: SP | L29: São José Dos Campos | M29: Jardim Satélite | N29: 227 | O29: Avenida Andrômeda | R29: Grupo Adidas | S29: Grupo Adidas | T29: Geral | W29: Fechada | X29: Demais Bandeiras
B30: 100 | C30: A | D30: Oscar Calcados Ltda | E30: 028 - Taub Ct | F30: 50915875001910 | G30: 688.713.183.115 | H30: 15 | I30: 28 | J30: 12010020 | K30: SP | L30: Taubaté | M30: Centro | N30: 54 | O30: Praça Dom Epaminondas | P30: Rua | Q30: N | R30: Grupo Oscar Calçados | S30: Grupo Oscar Calçados | T30: Grupo F1 | U30: ERICSON | V30: ESTEFAN | W30: Aberta | X30: Varejo Oscar | Y30: 350 | Z30: loja028@oscarcalcados.com.br
